UndefinedError

jinja2.exceptions.UndefinedError: 'datetime' is undefined
Traceback (most recent call last)

    File "/home/runner/workspace/.pythonlibs/lib/python3.11/site-packages/flask/app.py", line 1536, in __call__

    return self.wsgi_app(environ, start_response)
           ^^^^^^^^^^^^^^^^^^^^^^^^^^^^^^^^^^^^^^

    File "/home/runner/workspace/.pythonlibs/lib/python3.11/site-packages/werkzeug/middleware/proxy_fix.py", line 183, in __call__

    return self.app(environ, start_response)
           ^^^^^^^^^^^^^^^^^^^^^^^^^^^^^^^^^

    File "/home/runner/workspace/.pythonlibs/lib/python3.11/site-packages/flask/app.py", line 1514, in wsgi_app

    response = self.handle_exception(e)
               ^^^^^^^^^^^^^^^^^^^^^^^^

    File "/home/runner/workspace/.pythonlibs/lib/python3.11/site-packages/flask/app.py", line 1511, in wsgi_app

    response = self.full_dispatch_request()
               ^^^^^^^^^^^^^^^^^^^^^^^^^^^^

    File "/home/runner/workspace/.pythonlibs/lib/python3.11/site-packages/flask/app.py", line 919, in full_dispatch_request

    rv = self.handle_user_exception(e)
         ^^^^^^^^^^^^^^^^^^^^^^^^^^^^^

    File "/home/runner/workspace/.pythonlibs/lib/python3.11/site-packages/flask/app.py", line 917, in full_dispatch_request

    rv = self.dispatch_request()
         ^^^^^^^^^^^^^^^^^^^^^^^

    File "/home/runner/workspace/.pythonlibs/lib/python3.11/site-packages/flask/app.py", line 902, in dispatch_request

    return self.ensure_sync(self.view_functions[rule.endpoint])(**view_args)  # type: ignore[no-any-return]
           ^^^^^^^^^^^^^^^^^^^^^^^^^^^^^^^^^^^^^^^^^^^^^^^^^^^^^^^^^^^^^^^^^

    File "/home/runner/workspace/.pythonlibs/lib/python3.11/site-packages/flask_login/utils.py", line 290, in decorated_view

    return current_app.ensure_sync(func)(*args, **kwargs)
           ^^^^^^^^^^^^^^^^^^^^^^^^^^^^^^^^^^^^^^^^^^^^^^

    File "/home/runner/workspace/routes.py", line 281, in file_upload

    return render_template('file_upload.html')
           ^^^^^^^^^^^^^^^^^^^^^^^^^^^^^^^^^^^

    File "/home/runner/workspace/.pythonlibs/lib/python3.11/site-packages/flask/templating.py", line 150, in render_template

    return _render(app, template, context)
           ^^^^^^^^^^^^^^^^^^^^^^^^^^^^^^^

    File "/home/runner/workspace/.pythonlibs/lib/python3.11/site-packages/flask/templating.py", line 131, in _render

    rv = template.render(context)
         ^^^^^^^^^^^^^^^^^^^^^^^^

    File "/home/runner/workspace/.pythonlibs/lib/python3.11/site-packages/jinja2/environment.py", line 1295, in render

    self.environment.handle_exception()
    ^^^^^^^^^^^^^^^^^^^^^^^^^^^^^^^^^^^

    File "/home/runner/workspace/.pythonlibs/lib/python3.11/site-packages/jinja2/environment.py", line 942, in handle_exception

    raise rewrite_traceback_stack(source=source)
    ^^^^^^^^^^^^^^^^^^^^^^^^^^^^^^^^^^^^^^^^^^^^

    File "/home/runner/workspace/templates/file_upload.html", line 1, in top-level template code

    {% extends 'layout.html' %}

    File "/home/runner/workspace/templates/layout.html", line 103, in top-level template code

    {% block content %}{% endblock %}

    File "/home/runner/workspace/templates/file_upload.html", line 46, in block 'content'

    {% for year in range(datetime.now().year, datetime.now().year - 5, -1) %}

    File "/home/runner/workspace/.pythonlibs/lib/python3.11/site-packages/jinja2/environment.py", line 490, in getattr

    return getattr(obj, attribute)
           ^^^^^^^^^^^^^^^^^^^^^^^

    jinja2.exceptions.UndefinedError: 'datetime' is undefined

The debugger caught an exception in your WSGI application. You can now look at the traceback which led to the error.

To switch between the interactive traceback and the plaintext one, you can click on the "Traceback" headline. From the text traceback you can also create a paste of it.
